<?xml version="1.0" ?>
<robot name="spina">
<!-- base_link -->
  <link name="base_link"/>

  <!--########## Module1 ##########-->
  <!-- module1_lower_link -->
  <link name="module1_lower_link">
    <visual>
      <origin xyz="0 0 0" rpy="0 0 0"/>
      <geometry>
        <cylinder radius="0.1" length="0.02"/>
      </geometry>
      <material name="blue">
        <color rgba="0 0 1 1"/>
      </material>
    </visual>
    <collision>
      <origin xyz="0 0 0" rpy="0 0 0"/>
      <geometry>
        <cylinder radius="0.1" length="0.02"/>
      </geometry>
    </collision>
    <inertial>
      <origin xyz="0 0 0" rpy="0 0 0"/>
      <mass value="0.1"/>
      <inertia ixx="0.001" ixy="0" ixz="0" iyy="0.001" iyz="0" izz="0.001"/>
    </inertial>
  </link>

  <joint name="base_link_TO_module1_lower_link" type="fixed">
    <parent link="base_link"/>
    <child link="module1_lower_link"/>
    <origin xyz="0 0 0" rpy="0 0 0"/>
  </joint>

  <link name="module1_roll_link">
    <inertial>
      <origin xyz="0 0 0" rpy="0 0 0"/>
      <mass value="0.05"/>
      <inertia ixx="0.0005" ixy="0" ixz="0" iyy="0.0005" iyz="0" izz="0.0005"/>
    </inertial>
  </link>

  <joint name="module1_gimbal_roll" type="revolute">
    <parent link="module1_lower_link"/>
    <child link="module1_roll_link"/>
    <origin xyz="0 0 0.075" rpy="0 0 0"/>
    <axis xyz="1 0 0"/>
    <!-- Limit set to -30° to 30° which is approximately -0.5236 to 0.5236 radians -->
    <limit lower="-0.5236" upper="0.5236" effort="1" velocity="1"/>
  </joint>

  <!-- Intermediate link for roll rotation -->
  <link name="module1_pich_link">
    <inertial>
      <origin xyz="0 0 0" rpy="0 0 0"/>
      <mass value="0.05"/>
      <inertia ixx="0.0005" ixy="0" ixz="0" iyy="0.0005" iyz="0" izz="0.0005"/>
    </inertial>
  </link>

  <!-- Pitch joint: rotates about the Y-axis -->
  <joint name="module1_gimbal_pitch" type="revolute">
    <parent link="module1_roll_link"/>
    <child link="module1_pich_link"/>
    <origin xyz="0 0 0" rpy="0 0 0"/>
    <axis xyz="0 1 0"/>
    <!-- Limit set to -30° to 30° which is approximately -0.5236 to 0.5236 radians -->
    <limit lower="-0.5236" upper="0.5236" effort="1" velocity="1"/>
  </joint>

  <!-- Movable top disk -->
  <!-- Its center is positioned 7.5cm above the pivot so that the total center-to-center distance between disks is 15cm -->
  <link name="module2_upper_link">
    <visual>
      <origin xyz="0 0 0.075" rpy="0 0 0"/>
      <geometry>
        <cylinder radius="0.1" length="0.02"/>
      </geometry>
      <material name="red">
        <color rgba="1 0 0 1"/>
      </material>
    </visual>
    <collision>
      <origin xyz="0 0 0.075" rpy="0 0 0"/>
      <geometry>
        <cylinder radius="0.1" length="0.02"/>
      </geometry>
    </collision>
    <inertial>
      <origin xyz="0 0 0.075" rpy="0 0 0"/>
      <mass value="0.1"/>
      <inertia ixx="0.001" ixy="0" ixz="0" iyy="0.001" iyz="0" izz="0.001"/>
    </inertial>
  </link>

  <!-- Roll joint: rotates about the X-axis -->
  <joint name="gimbal_roll" type="revolute">
    <parent link="module1_pich_link"/>
    <child link="module2_upper_link"/>
    <origin xyz="0 0 0" rpy="0 0 0"/>
    <axis xyz="1 0 0"/>
    <!-- Limit set to -30° to 30° which is approximately -0.5236 to 0.5236 radians -->
    <limit lower="-0.5236" upper="0.5236" effort="1" velocity="1"/>
  </joint>

</robot>
