<robot name="spine_robot">
  <!-- Base link -->
  <link name="base_link">
    <inertial>
      <origin xyz="0 0 0" rpy="0 0 0"/>
      <mass value="1.0"/>
      <inertia ixx="0.01" ixy="0.0" ixz="0.0" iyy="0.01" iyz="0.0" izz="0.01"/>
    </inertial>
  </link>

  <!--
    This URDF defines a spine-like robot composed of 6 modules.
    Changes relative to a basic design:
      • The box geometry has been removed and replaced with a cylinder.
      • Each module is connected via a pair of revolute joints that enable rotation
        about two distinct axes:
          - An x-axis joint (providing, e.g., pitch motion)
          - A y-axis joint (providing yaw, as requested)
    Each module is implemented using an intermediate link to allow two rotational degrees-of-freedom per segment.
    The connection between modules occurs at the top of the cylinder (assuming a module length of 0.1 m).
  -->

  <!-- Module 1 -->
  <!-- Intermediate link for module 1 -->
  <link name="module1_intermediate">
    <inertial>
      <origin xyz="0 0 0" rpy="0 0 0"/>
      <mass value="0.01"/>
      <inertia ixx="0.001" ixy="0" ixz="0" iyy="0.001" iyz="0" izz="0.001"/>
    </inertial>
  </link>

  <!-- Actual module 1 with cylinder geometry -->
  <link name="module1">
    <visual>
      <origin xyz="0 0 0.05" rpy="0 0 0"/>
      <geometry>
        <cylinder length="0.1" radius="0.05"/>
      </geometry>
      <material name="Blue">
        <color rgba="0 0 1 1"/>
      </material>
    </visual>
  </link>

  <!-- Joint 1: X-axis rotation connecting base_link to module1_intermediate -->
  <joint name="joint1_x" type="revolute">
    <parent link="base_link"/>
    <child link="module1_intermediate"/>
    <origin xyz="0 0 0.1" rpy="0 0 0"/>
    <axis xyz="1 0 0"/>
    <limit lower="-1.57" upper="1.57" effort="10" velocity="1.0"/>
  </joint>

  <!-- Joint 1: Y-axis rotation connecting module1_intermediate to module1 -->
  <joint name="joint1_y" type="revolute">
    <parent link="module1_intermediate"/>
    <child link="module1"/>
    <origin xyz="0 0 0" rpy="0 0 0"/>
    <axis xyz="0 1 0"/>
    <limit lower="-1.57" upper="1.57" effort="10" velocity="1.0"/>
  </joint>

  <!-- Module 2 -->
  <link name="module2_intermediate">
    <inertial>
      <origin xyz="0 0 0" rpy="0 0 0"/>
      <mass value="0.01"/>
      <inertia ixx="0.001" ixy="0" ixz="0" iyy="0.001" iyz="0" izz="0.001"/>
    </inertial>
  </link>

  <link name="module2">
    <visual>
      <origin xyz="0 0 0.05" rpy="0 0 0"/>
      <geometry>
        <cylinder length="0.1" radius="0.05"/>
      </geometry>
      <material name="Green">
        <color rgba="0 1 0 1"/>
      </material>
    </visual>
  </link>

  <!-- Joint 2: X-axis rotation connecting module1 to module2_intermediate -->
  <joint name="joint2_x" type="revolute">
    <parent link="module1"/>
    <child link="module2_intermediate"/>
    <origin xyz="0 0 0.1" rpy="0 0 0"/>
    <axis xyz="1 0 0"/>
    <limit lower="-1.57" upper="1.57" effort="10" velocity="1.0"/>
  </joint>

  <!-- Joint 2: Y-axis rotation connecting module2_intermediate to module2 -->
  <joint name="joint2_y" type="revolute">
    <parent link="module2_intermediate"/>
    <child link="module2"/>
    <origin xyz="0 0 0" rpy="0 0 0"/>
    <axis xyz="0 1 0"/>
    <limit lower="-1.57" upper="1.57" effort="10" velocity="1.0"/>
  </joint>

  <!-- Module 3 -->
  <link name="module3_intermediate">
    <inertial>
      <origin xyz="0 0 0" rpy="0 0 0"/>
      <mass value="0.01"/>
      <inertia ixx="0.001" ixy="0" ixz="0" iyy="0.001" iyz="0" izz="0.001"/>
    </inertial>
  </link>

  <link name="module3">
    <visual>
      <origin xyz="0 0 0.05" rpy="0 0 0"/>
      <geometry>
        <cylinder length="0.1" radius="0.05"/>
      </geometry>
      <material name="Red">
        <color rgba="1 0 0 1"/>
      </material>
    </visual>
  </link>

  <!-- Joint 3: X-axis rotation connecting module2 to module3_intermediate -->
  <joint name="joint3_x" type="revolute">
    <parent link="module2"/>
    <child link="module3_intermediate"/>
    <origin xyz="0 0 0.1" rpy="0 0 0"/>
    <axis xyz="1 0 0"/>
    <limit lower="-1.57" upper="1.57" effort="10" velocity="1.0"/>
  </joint>

  <!-- Joint 3: Y-axis rotation connecting module3_intermediate to module3 -->
  <joint name="joint3_y" type="revolute">
    <parent link="module3_intermediate"/>
    <child link="module3"/>
    <origin xyz="0 0 0" rpy="0 0 0"/>
    <axis xyz="0 1 0"/>
    <limit lower="-1.57" upper="1.57" effort="10" velocity="1.0"/>
  </joint>

  <!-- Module 4 -->
  <link name="module4_intermediate">
    <inertial>
      <origin xyz="0 0 0" rpy="0 0 0"/>
      <mass value="0.01"/>
      <inertia ixx="0.001" ixy="0" ixz="0" iyy="0.001" iyz="0" izz="0.001"/>
    </inertial>
  </link>

  <link name="module4">
    <visual>
      <origin xyz="0 0 0.05" rpy="0 0 0"/>
      <geometry>
        <cylinder length="0.1" radius="0.05"/>
      </geometry>
      <material name="Yellow">
        <color rgba="1 1 0 1"/>
      </material>
    </visual>
  </link>

  <!-- Joint 4: X-axis rotation connecting module3 to module4_intermediate -->
  <joint name="joint4_x" type="revolute">
    <parent link="module3"/>
    <child link="module4_intermediate"/>
    <origin xyz="0 0 0.1" rpy="0 0 0"/>
    <axis xyz="1 0 0"/>
    <limit lower="-1.57" upper="1.57" effort="10" velocity="1.0"/>
  </joint>

  <!-- Joint 4: Y-axis rotation connecting module4_intermediate to module4 -->
  <joint name="joint4_y" type="revolute">
    <parent link="module4_intermediate"/>
    <child link="module4"/>
    <origin xyz="0 0 0" rpy="0 0 0"/>
    <axis xyz="0 1 0"/>
    <limit lower="-1.57" upper="1.57" effort="10" velocity="1.0"/>
  </joint>

  <!-- Module 5 -->
  <link name="module5_intermediate">
    <inertial>
      <origin xyz="0 0 0" rpy="0 0 0"/>
      <mass value="0.01"/>
      <inertia ixx="0.001" ixy="0" ixz="0" iyy="0.001" iyz="0" izz="0.001"/>
    </inertial>
  </link>

  <link name="module5">
    <visual>
      <origin xyz="0 0 0.05" rpy="0 0 0"/>
      <geometry>
        <cylinder length="0.1" radius="0.05"/>
      </geometry>
      <material name="Cyan">
        <color rgba="0 1 1 1"/>
      </material>
    </visual>
  </link>

  <!-- Joint 5: X-axis rotation connecting module4 to module5_intermediate -->
  <joint name="joint5_x" type="revolute">
    <parent link="module4"/>
    <child link="module5_intermediate"/>
    <origin xyz="0 0 0.1" rpy="0 0 0"/>
    <axis xyz="1 0 0"/>
    <limit lower="-1.57" upper="1.57" effort="10" velocity="1.0"/>
  </joint>

  <!-- Joint 5: Y-axis rotation connecting module5_intermediate to module5 -->
  <joint name="joint5_y" type="revolute">
    <parent link="module5_intermediate"/>
    <child link="module5"/>
    <origin xyz="0 0 0" rpy="0 0 0"/>
    <axis xyz="0 1 0"/>
    <limit lower="-1.57" upper="1.57" effort="10" velocity="1.0"/>
  </joint>

  <!-- Module 6 -->
  <link name="module6_intermediate">
    <inertial>
      <origin xyz="0 0 0" rpy="0 0 0"/>
      <mass value="0.01"/>
      <inertia ixx="0.001" ixy="0" ixz="0" iyy="0.001" iyz="0" izz="0.001"/>
    </inertial>
  </link>

  <link name="module6">
    <visual>
      <origin xyz="0 0 0.05" rpy="0 0 0"/>
      <geometry>
        <cylinder length="0.1" radius="0.05"/>
      </geometry>
      <material name="Magenta">
        <color rgba="1 0 1 1"/>
      </material>
    </visual>
  </link>

  <!-- Joint 6: X-axis rotation connecting module5 to module6_intermediate -->
  <joint name="joint6_x" type="revolute">
    <parent link="module5"/>
    <child link="module6_intermediate"/>
    <origin xyz="0 0 0.1" rpy="0 0 0"/>
    <axis xyz="1 0 0"/>
    <limit lower="-1.57" upper="1.57" effort="10" velocity="1.0"/>
  </joint>

  <!-- Joint 6: Y-axis rotation connecting module6_intermediate to module6 -->
  <joint name="joint6_y" type="revolute">
    <parent link="module6_intermediate"/>
    <child link="module6"/>
    <origin xyz="0 0 0" rpy="0 0 0"/>
    <axis xyz="0 1 0"/>
    <limit lower="-1.57" upper="1.57" effort="10" velocity="1.0"/>
  </joint>

</robot>
