<?xml version="1.0"?>
<robot name="spine_robot">

  <!-- 基底リンク -->
  <link name="base_link">
    <visual>
      <geometry><cylinder radius="0.1" length="0.15"/></geometry>
    </visual>
    <collision>
      <geometry><cylinder radius="0.1" length="0.15"/></geometry>
    </collision>
    <inertial>
      <mass value="1.0"/>
      <origin xyz="0 0 0" rpy="0 0 0"/>
      <inertia ixx="0.001" iyy="0.001" izz="0.001" ixy="0" ixz="0" iyz="0"/>
    </inertial>
  </link>

  <!-- 以下、各モジュール毎に pitch → roll → module_link の順でジョイントを定義 -->
  <!-- モジュール間隔は origin xyz="0 0 0.15" で 15cm -->
  <!-- axis: pitch は y 軸、roll は x 軸 -->

  <!-- Module 1 -->
  <link name="module1_pitch_link"/>
  <joint name="pitch1" type="revolute">
    <parent link="base_link"/>
    <child  link="module1_pitch_link"/>
    <origin xyz="0 0 0.15" rpy="0 0 0"/>
    <axis  xyz="0 1 0"/>
    <limit lower="-0.5236" upper="0.5236" effort="10" velocity="1.0"/>
  </joint>

  <link name="module1_roll_link"/>
  <joint name="roll1" type="revolute">
    <parent link="module1_pitch_link"/>
    <child  link="module1_roll_link"/>
    <origin xyz="0 0 0" rpy="0 0 0"/>
    <axis  xyz="1 0 0"/>
    <limit lower="-0.5236" upper="0.5236" effort="10" velocity="1.0"/>
  </joint>

  <link name="module1_link">
    <visual>
      <geometry><cylinder radius="0.1" length="0.15"/></geometry>
      <origin xyz="0 0 0" rpy="0 0 0"/>
    </visual>
    <collision>
      <geometry><cylinder radius="0.1" length="0.15"/></geometry>
    </collision>
    <inertial>
      <mass value="0.8"/>
      <origin xyz="0 0 0" rpy="0 0 0"/>
      <inertia ixx="0.0008" iyy="0.0008" izz="0.0008" ixy="0" ixz="0" iyz="0"/>
    </inertial>
  </link>

  <!-- Module 2 -->
  <link name="module2_pitch_link"/>
  <joint name="pitch2" type="revolute">
    <parent link="module1_link"/>
    <child  link="module2_pitch_link"/>
    <origin xyz="0 0 0.15" rpy="0 0 0"/>
    <axis  xyz="0 1 0"/>
    <limit lower="-0.5236" upper="0.5236" effort="10" velocity="1.0"/>
  </joint>

  <link name="module2_roll_link"/>
  <joint name="roll2" type="revolute">
    <parent link="module2_pitch_link"/>
    <child  link="module2_roll_link"/>
    <origin xyz="0 0 0" rpy="0 0 0"/>
    <axis  xyz="1 0 0"/>
    <limit lower="-0.5236" upper="0.5236" effort="10" velocity="1.0"/>
  </joint>

  <link name="module2_link">
    <visual><geometry><cylinder radius="0.1" length="0.15"/></geometry></visual>
    <collision><geometry><cylinder radius="0.1" length="0.15"/></geometry></collision>
    <inertial>
      <mass value="0.8"/>
      <origin xyz="0 0 0" rpy="0 0 0"/>
      <inertia ixx="0.0008" iyy="0.0008" izz="0.0008" ixy="0" ixz="0" iyz="0"/>
    </inertial>
  </link>

  <!-- Module 3 -->
  <link name="module3_pitch_link"/>
  <joint name="pitch3" type="revolute">
    <parent link="module2_link"/>
    <child  link="module3_pitch_link"/>
    <origin xyz="0 0 0.15" rpy="0 0 0"/>
    <axis  xyz="0 1 0"/>
    <limit lower="-0.5236" upper="0.5236" effort="10" velocity="1.0"/>
  </joint>

  <link name="module3_roll_link"/>
  <joint name="roll3" type="revolute">
    <parent link="module3_pitch_link"/>
    <child  link="module3_roll_link"/>
    <origin xyz="0 0 0" rpy="0 0 0"/>
    <axis  xyz="1 0 0"/>
    <limit lower="-0.5236" upper="0.5236" effort="10" velocity="1.0"/>
  </joint>

  <link name="module3_link">
    <visual><geometry><cylinder radius="0.1" length="0.15"/></geometry></visual>
    <collision><geometry><cylinder radius="0.1" length="0.15"/></geometry></collision>
    <inertial>
      <mass value="0.8"/>
      <origin xyz="0 0 0" rpy="0 0 0"/>
      <inertia ixx="0.0008" iyy="0.0008" izz="0.0008" ixy="0" ixz="0" iyz="0"/>
    </inertial>
  </link>

  <!-- Module 4 -->
  <link name="module4_pitch_link"/>
  <joint name="pitch4" type="revolute">
    <parent link="module3_link"/>
    <child  link="module4_pitch_link"/>
    <origin xyz="0 0 0.15" rpy="0 0 0"/>
    <axis  xyz="0 1 0"/>
    <limit lower="-0.5236" upper="0.5236" effort="10" velocity="1.0"/>
  </joint>

  <link name="module4_roll_link"/>
  <joint name="roll4" type="revolute">
    <parent link="module4_pitch_link"/>
    <child  link="module4_roll_link"/>
    <origin xyz="0 0 0" rpy="0 0 0"/>
    <axis  xyz="1 0 0"/>
    <limit lower="-0.5236" upper="0.5236" effort="10" velocity="1.0"/>
  </joint>

  <link name="module4_link">
    <visual><geometry><cylinder radius="0.1" length="0.15"/></geometry></visual>
    <collision><geometry><cylinder radius="0.1" length="0.15"/></geometry></collision>
    <inertial>
      <mass value="0.8"/>
      <origin xyz="0 0 0" rpy="0 0 0"/>
      <inertia ixx="0.0008" iyy="0.0008" izz="0.0008" ixy="0" ixz="0" iyz="0"/>
    </inertial>
  </link>

  <!-- Module 5 -->
  <link name="module5_pitch_link"/>
  <joint name="pitch5" type="revolute">
    <parent link="module4_link"/>
    <child  link="module5_pitch_link"/>
    <origin xyz="0 0 0.15" rpy="0 0 0"/>
    <axis  xyz="0 1 0"/>
    <limit lower="-0.5236" upper="0.5236" effort="10" velocity="1.0"/>
  </joint>

  <link name="module5_roll_link"/>
  <joint name="roll5" type="revolute">
    <parent link="module5_pitch_link"/>
    <child  link="module5_roll_link"/>
    <origin xyz="0 0 0" rpy="0 0 0"/>
    <axis  xyz="1 0 0"/>
    <limit lower="-0.5236" upper="0.5236" effort="10" velocity="1.0"/>
  </joint>

  <link name="module5_link">
    <visual><geometry><cylinder radius="0.1" length="0.15"/></geometry></visual>
    <collision><geometry><cylinder radius="0.1" length="0.15"/></geometry></collision>
    <inertial>
      <mass value="0.8"/>
      <origin xyz="0 0 0" rpy="0 0 0"/>
      <inertia ixx="0.0008" iyy="0.0008" izz="0.0008" ixy="0" ixz="0" iyz="0"/>
    </inertial>
  </link>

  <!-- Module 6 -->
  <link name="module6_pitch_link"/>
  <joint name="pitch6" type="revolute">
    <parent link="module5_link"/>
    <child  link="module6_pitch_link"/>
    <origin xyz="0 0 0.15" rpy="0 0 0"/>
    <axis  xyz="0 1 0"/>
    <limit lower="-0.5236" upper="0.5236" effort="10" velocity="1.0"/>
  </joint>

  <link name="module6_roll_link"/>
  <joint name="roll6" type="revolute">
    <parent link="module6_pitch_link"/>
    <child  link="module6_roll_link"/>
    <origin xyz="0 0 0" rpy="0 0 0"/>
    <axis  xyz="1 0 0"/>
    <limit lower="-0.5236" upper="0.5236" effort="10" velocity="1.0"/>
  </joint>

  <link name="module6_link">
    <visual><geometry><cylinder radius="0.1" length="0.15"/></geometry></visual>
    <collision><geometry><cylinder radius="0.1" length="0.15"/></geometry></collision>
    <inertial>
      <mass value="0.8"/>
      <origin xyz="0 0 0" rpy="0 0 0"/>
      <inertia ixx="0.0008" iyy="0.0008" izz="0.0008" ixy="0" ixz="0" iyz="0"/>
    </inertial>
  </link>

</robot>
